Workbook

Sheet Instructions
C3: Possible solution
C4: Setup report to generate automatically each quarter emailed to FCM
C5: Drop copy of report in the appropriate tab
C6: Have formulas setup to summarize each company
C7: Populate summary tab

Sheet Summary
A1: 2026 Net Interest Income by Company Code
A2: Paste each quarterly Kyriba report (INTEREST_INC) unchanged into its QX tab; this tab sums column F by company code.
A4: Company | B4: 1Q | C4: 2Q | D4: 3Q | E4: 4Q | F4: 2026 Total
A5: 1000 | B5: =SUMIFS('1Q'!$F:$F,'1Q'!$A:$A,"1000",'1Q'!$B:$B,"<>"&$B$29) -> 0 | C5: =SUMIFS('2Q'!$F:$F,'2Q'!$A:$A,"1000",'2Q'!$B:$B,"<>"&$B$29) -> 0 | D5: =SUMIFS('3Q'!$F:$F,'3Q'!$A:$A,"1000",'3Q'!$B:$B,"<>"&$B$29) -> 9295165.2 | E5: =SUMIFS('4Q'!$F:$F,'4Q'!$A:$A,"1000",'4Q'!$B:$B,"<>"&$B$29) -> 0 | F5: =SUM(B5:E5) -> 9295165.2
A6: 1000 INC STI | B6: =SUMIFS('1Q'!$F:$F,'1Q'!$B:$B,$B$29) -> 0 | C6: =SUMIFS('2Q'!$F:$F,'2Q'!$B:$B,$B$29) -> 0 | D6: =SUMIFS('3Q'!$F:$F,'3Q'!$B:$B,$B$29) -> 5933452.9 | E6: =SUMIFS('4Q'!$F:$F,'4Q'!$B:$B,$B$29) -> 0 | F6: =SUM(B6:E6) -> 5933452.9
A7: 1012 | B7: =SUMIFS('1Q'!$F:$F,'1Q'!$A:$A,$A7) -> 0 | C7: =SUMIFS('2Q'!$F:$F,'2Q'!$A:$A,$A7) -> 0 | D7: =SUMIFS('3Q'!$F:$F,'3Q'!$A:$A,$A7) -> 422686.17 | E7: =SUMIFS('4Q'!$F:$F,'4Q'!$A:$A,$A7) -> 0 | F7: =SUM(B7:E7) -> 422686.17
A8: 1100 | B8: =SUMIFS('1Q'!$F:$F,'1Q'!$A:$A,$A8) -> 0 | C8: =SUMIFS('2Q'!$F:$F,'2Q'!$A:$A,$A8) -> 0 | D8: =SUMIFS('3Q'!$F:$F,'3Q'!$A:$A,$A8) -> 366355.17 | E8: =SUMIFS('4Q'!$F:$F,'4Q'!$A:$A,$A8) -> 0 | F8: =SUM(B8:E8) -> 366355.17
A9: 1200 | B9: =SUMIFS('1Q'!$F:$F,'1Q'!$A:$A,$A9) -> 0 | C9: =SUMIFS('2Q'!$F:$F,'2Q'!$A:$A,$A9) -> 0 | D9: =SUMIFS('3Q'!$F:$F,'3Q'!$A:$A,$A9) -> 115705.3 | E9: =SUMIFS('4Q'!$F:$F,'4Q'!$A:$A,$A9) -> 0 | F9: =SUM(B9:E9) -> 115705.3
A10: 1400 | B10: =SUMIFS('1Q'!$F:$F,'1Q'!$A:$A,$A10) -> 0 | C10: =SUMIFS('2Q'!$F:$F,'2Q'!$A:$A,$A10) -> 0 | D10: =SUMIFS('3Q'!$F:$F,'3Q'!$A:$A,$A10) -> 184690.59 | E10: =SUMIFS('4Q'!$F:$F,'4Q'!$A:$A,$A10) -> 0 | F10: =SUM(B10:E10) -> 184690.59
A11: 1500 | B11: =SUMIFS('1Q'!$F:$F,'1Q'!$A:$A,$A11) -> 0 | C11: =SUMIFS('2Q'!$F:$F,'2Q'!$A:$A,$A11) -> 0 | D11: =SUMIFS('3Q'!$F:$F,'3Q'!$A:$A,$A11) -> 99887.06 | E11: =SUMIFS('4Q'!$F:$F,'4Q'!$A:$A,$A11) -> 0 | F11: =SUM(B11:E11) -> 99887.06
A12: 1800 | B12: =SUMIFS('1Q'!$F:$F,'1Q'!$A:$A,$A12) -> 0 | C12: =SUMIFS('2Q'!$F:$F,'2Q'!$A:$A,$A12) -> 0 | D12: =SUMIFS('3Q'!$F:$F,'3Q'!$A:$A,$A12) -> 174818.72 | E12: =SUMIFS('4Q'!$F:$F,'4Q'!$A:$A,$A12) -> 0 | F12: =SUM(B12:E12) -> 174818.72
A13: 1810 | B13: =SUMIFS('1Q'!$F:$F,'1Q'!$A:$A,$A13) -> 0 | C13: =SUMIFS('2Q'!$F:$F,'2Q'!$A:$A,$A13) -> 0 | D13: =SUMIFS('3Q'!$F:$F,'3Q'!$A:$A,$A13) -> 1844711.8 | E13: =SUMIFS('4Q'!$F:$F,'4Q'!$A:$A,$A13) -> 0 | F13: =SUM(B13:E13) -> 1844711.8
A14: 1825 | B14: =SUMIFS('1Q'!$F:$F,'1Q'!$A:$A,$A14) -> 0 | C14: =SUMIFS('2Q'!$F:$F,'2Q'!$A:$A,$A14) -> 0 | D14: =SUMIFS('3Q'!$F:$F,'3Q'!$A:$A,$A14) -> 97463.2 | E14: =SUMIFS('4Q'!$F:$F,'4Q'!$A:$A,$A14) -> 0 | F14: =SUM(B14:E14) -> 97463.2
A15: 1840 | B15: =SUMIFS('1Q'!$F:$F,'1Q'!$A:$A,$A15) -> 0 | C15: =SUMIFS('2Q'!$F:$F,'2Q'!$A:$A,$A15) -> 0 | D15: =SUMIFS('3Q'!$F:$F,'3Q'!$A:$A,$A15) -> 13505.56 | E15: =SUMIFS('4Q'!$F:$F,'4Q'!$A:$A,$A15) -> 0 | F15: =SUM(B15:E15) -> 13505.56
A16: 2200 | B16: =SUMIFS('1Q'!$F:$F,'1Q'!$A:$A,$A16) -> 0 | C16: =SUMIFS('2Q'!$F:$F,'2Q'!$A:$A,$A16) -> 0 | D16: =SUMIFS('3Q'!$F:$F,'3Q'!$A:$A,$A16) -> 624437.13 | E16: =SUMIFS('4Q'!$F:$F,'4Q'!$A:$A,$A16) -> 0 | F16: =SUM(B16:E16) -> 624437.13
A17: 2400 | B17: =SUMIFS('1Q'!$F:$F,'1Q'!$A:$A,$A17) -> 0 | C17: =SUMIFS('2Q'!$F:$F,'2Q'!$A:$A,$A17) -> 0 | D17: =SUMIFS('3Q'!$F:$F,'3Q'!$A:$A,$A17) -> 1708655.1 | E17: =SUMIFS('4Q'!$F:$F,'4Q'!$A:$A,$A17) -> 0 | F17: =SUM(B17:E17) -> 1708655.1
A18: 2500 | B18: =SUMIFS('1Q'!$F:$F,'1Q'!$A:$A,$A18) -> 0 | C18: =SUMIFS('2Q'!$F:$F,'2Q'!$A:$A,$A18) -> 0 | D18: =SUMIFS('3Q'!$F:$F,'3Q'!$A:$A,$A18) -> 2958273.5 | E18: =SUMIFS('4Q'!$F:$F,'4Q'!$A:$A,$A18) -> 0 | F18: =SUM(B18:E18) -> 2958273.5
... A22: 2900 | B22: =SUMIFS('1Q'!$F:$F,'1Q'!$A:$A,$A22) -> 0 | C22: =SUMIFS('2Q'!$F:$F,'2Q'!$A:$A,$A22) -> 0 | D22: =SUMIFS('3Q'!$F:$F,'3Q'!$A:$A,$A22) -> 1717227.6 | E22: =SUMIFS('4Q'!$F:$F,'4Q'!$A:$A,$A22) -> 0 | F22: =SUM(B22:E22) -> 1717227.6
A23: Grand Total | B23: =SUM(B5:B22) -> 0 | C23: =SUM(C5:C22) -> 0 | D23: =SUM(D5:D22) -> 25847242 | E23: =SUM(E5:E22) -> 0 | F23: =SUM(F5:F22) -> 25847242
A25: Check: tab total less summary (s/b 0) | B25: =ROUND(SUM('1Q'!$F:$F)-B23,2) -> 0 | C25: =ROUND(SUM('2Q'!$F:$F)-C23,2) -> 0 | D25: =ROUND(SUM('3Q'!$F:$F)-D23,2) -> 0 | E25: =ROUND(SUM('4Q'!$F:$F)-E23,2) -> 0
A27: Notes
A28: Company 1000 excludes the account below; that account is reported on the "1000 INC STI" line.
A29: Account split out of 1000: | B29: 1000JPMUS222
A30: A non-zero check means a tab has amounts under a company code not listed above - add a row for it.

Sheet 1Q
A1: !Q

Sheet 2Q

Sheet 3Q
A1: Report name: Cash flow ledger | E1: Template: Interest Income(INTEREST_INC)
A2: Cash flow ledger | E2: Time: 10/22/2026 - 4:32:39 PM
A3: From: 07/01/2026 to 09/30/2026 | E3: Date type: Value date
A4: Separate ledger: No: unique ledger | E4: Order by: Company/Budget code/None
A5: Amounts: In unit | E5: Currency
A6: Amount range: | E6: Reference range:
A7: Origin: All | E7: Flow status: AC
A8: Entity: Multiple
A9: Company | B9: Account | C9: Budget | D9: Value date | E9: Flow amount (currency) | F9: Flow amount (value) | G9: Description
A10: 1000 | B10: 1000JPMUS222 | C10: +INT_INC | D10: 07/01/2026 | E10: +USD | F10: 368001.46 | G10: YOUR REF=CAP OF 26/07/01,REC FROM=00000000323363792 DST ASSET MANAGER SOLUTIONS, INC. A/A/F JPM FUNDS FOR JPMORGAN 2000 CROWN COLONY DR QUINCY MA 02169-0953 US,B/O CUSTOMER=0002430/00005023346 AFLAC INCORPORATED ATTN CORPORATE TREASURY 1932 WYNNTON RD,REMARK=COLUMBUS GA 31999-0001 DEBIT REF 0129140745180107,REC GFP=07011319
A11: 1000 | B11: 1000JPMUS269 | C11: +INT_INC | D11: 07/01/2026 | E11: +USD | F11: 1023.38 | G11: REMARK=NEXT DAY INTEREST PAYMENT FROM ACCOUNT 000000550381344
A12: 1000 | B12: 1000JPMUS269 | C12: +INT_INC | D12: 07/01/2026 | E12: +USD | F12: 1552481.5 | G12: YOUR REF=NOTPROVIDED,REC FROM=00000000066001633 J.P. MORGAN SECURITIES LLC 383 MADISON AVE NEW YORK NY 10179-0001 US,B/O CUSTOMER=/7528076412 AFLAC INCORPORATED ATTN: CORPORATE FINANCE 1932 WYNNTON ROAD COLUMBUS GA31999-0002,B/O BANK=J.P. MORGAN SECURITIES LLC 383 MADISON AVENUE NEW YORK NY US,REMARK=ICD DIVIDEND /OCMT/USD1552481,51/ DEBIT REF 2607010591100001,REC GFP=07011647
A13: 1000 | B13: 1000JPMUS222 | C13: +INT_INC | D13: 07/01/2026 | E13: +USD | F13: 1034525.4 | G13: YOUR REF=NOTPROVIDED,REC FROM=00000000066001633 J.P. MORGAN SECURITIES LLC 383 MADISON AVE NEW YORK NY 10179-0001 US,B/O CUSTOMER=/7528149219 AFLAC INCORPORATED ST INVESTMENTS (AFLSTI) 1932 WYNNTON ROAD COLUMBUS GA31999-0002,B/O BANK=J.P. MORGAN SECURITIES LLC 383 MADISON AVENUE NEW YORK NY US,REMARK=ICD DIVIDEND /OCMT/USD1034525,36/ DEBIT REF 2607010601300001,REC GFP=07011652
A14: 1000 | B14: 1000JPMUS269 | C14: +INT_INC | D14: 07/01/2026 | E14: +USD | F14: 6727.33 | G14: REMARK=NEXT DAY INTEREST PAYMENT FROM ACCOUNT 000000639688222
A15: 1000 | B15: 1000JPMUS269 | C15: +INT_INC | D15: 07/01/2026 | E15: +USD | F15: 7685.55 | G15: REMARK=NEXT DAY INTEREST PAYMENT FROM ACCOUNT 000000550378878
A16: 1000 | B16: 1000JPMUS269 | C16: +INT_INC | D16: 07/01/2026 | E16: +USD | F16: 1773.65 | G16: REMARK=NEXT DAY INTEREST PAYMENT FROM ACCOUNT 000000890456759
A17: 1000 | B17: 1000JPMUS269 | C17: +INT_INC | D17: 07/01/2026 | E17: +USD | F17: 414.68 | G17: REMARK=NEXT DAY INTEREST PAYMENT FROM ACCOUNT 000000890456775
A18: 1000 | B18: 1000JPMUS269 | C18: +INT_INC | D18: 07/01/2026 | E18: +USD | F18: 1268.64 | G18: REMARK=NEXT DAY INTEREST PAYMENT FROM ACCOUNT 000000773092231
A19: 1000 | B19: 1000JPMUS269 | C19: +INT_INC | D19: 07/01/2026 | E19: +USD | F19: 1025.47 | G19: REMARK=NEXT DAY INTEREST PAYMENT FROM ACCOUNT 000000550378910
A20: 1000 | B20: 1000CITUS498 | C20: +INT_INC | D20: 07/01/2026 | E20: +USD | F20: 312609.08 | G20: FR:INTERESTENDT:20260701TRID:NONREFPY:INTEREST ON DEMAND DEPOSIT ACCOUNT AVAILABLE BALANCE
A21: 1000 | B21: 1000JPMUS269 | C21: +INT_INC | D21: 07/02/2026 | E21: +USD | F21: 17750.09 | G21: YOUR REF=NOTPROVIDED,REC FROM=00000000066001633 J.P. MORGAN SECURITIES LLC 383 MADISON AVE NEW YORK NY 10179-0001 US,B/O CUSTOMER=/7528076412 AFLAC INCORPORATED ATTN: CORPORATE FINANCE 1932 WYNNTON ROAD COLUMBUS GA31999-0002,B/O BANK=J.P. MORGAN SECURITIES LLC 383 MADISON AVENUE NEW YORK NY US,REMARK=ICD DIVIDEND /OCMT/USD17750,09/ DEBIT REF 2607020582500001,REC GFP=07022014
... A70: 1000 | B70: 1000PNCUS489 | C70: +INT_INC | D70: 09/30/2026 | E70: +USD | F70: 76002.31 | G70: INTEREST PAYMENT
B71: Company 1000 | D71: D:-USD 0 | G71: Fee.
A72: 1012 | B72: 1012JPMUS900 | C72: +INT_INC | D72: 07/01/2026 | E72: +USD | F72: 136134.72 | G72: YOUR REF=NOTPROVIDED,REC FROM=00000000066001633 J.P. MORGAN SECURITIES LLC 383 MADISON AVE NEW YORK NY 10179-0001 US,B/O CUSTOMER=/7528157618 AFLAC GI HOLDINGS LLC 1932 WYNNTON ROAD COLUMBUS GA31999-0002,B/O BANK=J.P. MORGAN SECURITIES LLC 383 MADISON AVENUE NEW YORK NY US,REMARK=ICD DIVIDEND /OCMT/USD136134,72/ DEBIT REF 2607010397400001,REC GFP=07011342
A73: 1012 | B73: 1012JPMUS900 | C73: +INT_INC | D73: 07/31/2026 | E73: +USD | F73: 877.14 | G73: REMARK=INTEREST PAYMENT
A74: 1012 | B74: 1012JPMUS900 | C74: +INT_INC | D74: 08/03/2026 | E74: +USD | F74: 141331.44 | G74: YOUR REF=NOTPROVIDED,REC FROM=00000000066001633 J.P. MORGAN SECURITIES LLC 383 MADISON AVE NEW YORK NY 10179-0001 US,B/O CUSTOMER=/7528157618 AFLAC GI HOLDINGS LLC 1932 WYNNTON ROAD COLUMBUS GA31999-0002,B/O BANK=J.P. MORGAN SECURITIES LLC 383 MADISON AVENUE NEW YORK NY US,REMARK=ICD DIVIDEND /OCMT/USD141331,44/ DEBIT REF 2608030403400001,REC GFP=08031602
A75: 1012 | B75: 1012JPMUS900 | C75: +INT_INC | D75: 08/31/2026 | E75: +USD | F75: 1131 | G75: REMARK=INTEREST PAYMENT
A76: 1012 | B76: 1012JPMUS900 | C76: +INT_INC | D76: 09/01/2026 | E76: +USD | F76: 131107.39 | G76: YOUR REF=NOTPROVIDED,REC FROM=00000000066001633 J.P. MORGAN SECURITIES LLC 383 MADISON AVE NEW YORK NY 10179-0001 US,B/O CUSTOMER=/7528157618 AFLAC GI HOLDINGS LLC 1932 WYNNTON ROAD COLUMBUS GA31999-0002,B/O BANK=J.P. MORGAN SECURITIES LLC 383 MADISON AVENUE NEW YORK NY US,REMARK=ICD DIVIDEND /OCMT/USD131107,39/ DEBIT REF 2609011721600001,REC GFP=09012013
A77: 1012 | B77: 1012JPMUS900 | C77: +INT_INC | D77: 09/02/2026 | E77: +USD | F77: 11262.75 | G77: YOUR REF=NOTPROVIDED,REC FROM=00000000066001633 J.P. MORGAN SECURITIES LLC 383 MADISON AVE NEW YORK NY 10179-0001 US,B/O CUSTOMER=/7528157618 AFLAC GI HOLDINGS LLC 1932 WYNNTON ROAD COLUMBUS GA31999-0002,B/O BANK=J.P. MORGAN SECURITIES LLC 383 MADISON AVENUE NEW YORK NY US,REMARK=ICD DIVIDEND /OCMT/USD11262,75/ DEBIT REF 2609020198300001,REC GFP=09021438
A78: 1012 | B78: 1012JPMUS900 | C78: +INT_INC | D78: 09/30/2026 | E78: +USD | F78: 841.73 | G78: REMARK=INTEREST PAYMENT
B79: Company 1012 | D79: D:-USD 0 | G79: Fee.
A80: 1100 | B80: 1100JPMUS783 | C80: +INT_INC | D80: 07/01/2026 | E80: +USD | F80: 112859.26 | G80: YOUR REF=NOTPROVIDED,REC FROM=00000000066001633 J.P. MORGAN SECURITIES LLC 383 MADISON AVE NEW YORK NY 10179-0001 US,B/O CUSTOMER=/7528076511 AFLAC INTERNATIONAL INC ATTN: CORPORATE FINANCE 1932 WYNNTON ROAD COLUMBUS GA31999-0002,B/O BANK=J.P. MORGAN SECURITIES LLC 383 MADISON AVENUE NEW YORK NY US,REMARK=ICD DIVIDEND /OCMT/USD112859,26/ DEBIT REF 2607010565000001,REC GFP=07011622
A81: 1100 | B81: 1100JPMUS783 | C81: +INT_INC | D81: 07/01/2026 | E81: +USD | F81: 110.14 | G81: REMARK=NEXT DAY INTEREST PAYMENT FROM ACCOUNT 000000773093999
A82: 1100 | B82: 1100JPMUS783 | C82: +INT_INC | D82: 07/14/2026 | E82: +USD | F82: 1701.63 | G82: YOUR REF=NOTPROVIDED,REC FROM=00000000066001633 J.P. MORGAN SECURITIES LLC 383 MADISON AVE NEW YORK NY 10179-0001 US,B/O CUSTOMER=/7528076511 AFLAC INTERNATIONAL INC ATTN: CORPORATE FINANCE 1932 WYNNTON ROAD COLUMBUS GA31999-0002,B/O BANK=J.P. MORGAN SECURITIES LLC 383 MADISON AVENUE NEW YORK NY US,REMARK=ICD DIVIDEND /OCMT/USD1701,63/ DEBIT REF 2607140577900001,REC GFP=07142112
A83: 1100 | B83: 1100JPMUS783 | C83: +INT_INC | D83: 07/14/2026 | E83: +USD | F83: 633.44 | G83: YOUR REF=NOTPROVIDED,REC FROM=00000000066001633 J.P. MORGAN SECURITIES LLC 383 MADISON AVE NEW YORK NY 10179-0001 US,B/O CUSTOMER=/7528076511 AFLAC INTERNATIONAL INC ATTN: CORPORATE FINANCE 1932 WYNNTON ROAD COLUMBUS GA31999-0002,B/O BANK=J.P. MORGAN SECURITIES LLC 383 MADISON AVENUE NEW YORK NY US,REMARK=ICD DIVIDEND /OCMT/USD633,44/ DEBIT REF 2607140241900001,REC GFP=07141512
A84: 1100 | B84: 1100JPMUS783 | C84: +INT_INC | D84: 07/14/2026 | E84: +USD | F84: 24014.3 | G84: YOUR REF=NOTPROVIDED,REC FROM=00000000066001633 J.P. MORGAN SECURITIES LLC 383 MADISON AVE NEW YORK NY 10179-0001 US,B/O CUSTOMER=/7528076511 AFLAC INTERNATIONAL INC ATTN: CORPORATE FINANCE 1932 WYNNTON ROAD COLUMBUS GA31999-0002,B/O BANK=J.P. MORGAN SECURITIES LLC 383 MADISON AVENUE NEW YORK NY US,REMARK=ICD DIVIDEND /OCMT/USD24014,3/ DEBIT REF 2607140241200001,REC GFP=07141512
A85: 1100 | B85: 1100JPMUS783 | C85: +INT_INC | D85: 07/14/2026 | E85: +USD | F85: 6053.27 | G85: YOUR REF=NOTPROVIDED,REC FROM=00000000066001633 J.P. MORGAN SECURITIES LLC 383 MADISON AVE NEW YORK NY 10179-0001 US,B/O CUSTOMER=/7528076511 AFLAC INTERNATIONAL INC ATTN: CORPORATE FINANCE 1932 WYNNTON ROAD COLUMBUS GA31999-0002,B/O BANK=J.P. MORGAN SECURITIES LLC 383 MADISON AVENUE NEW YORK NY US,REMARK=ICD DIVIDEND /OCMT/USD6053,27/ DEBIT REF 2607140574500001,REC GFP=07142112
A86: 1100 | B86: 1100JPMUS783 | C86: +INT_INC | D86: 07/31/2026 | E86: +USD | F86: 1404.27 | G86: REMARK=INTEREST PAYMENT
A87: 1100 | B87: 1100JPMUS783 | C87: +INT_INC | D87: 08/03/2026 | E87: +USD | F87: 88816.09 | G87: YOUR REF=NOTPROVIDED,REC FROM=00000000066001633 J.P. MORGAN SECURITIES LLC 383 MADISON AVE NEW YORK NY 10179-0001 US,B/O CUSTOMER=/7528076511 AFLAC INTERNATIONAL INC ATTN: CORPORATE FINANCE 1932 WYNNTON ROAD COLUMBUS GA31999-0002,B/O BANK=J.P. MORGAN SECURITIES LLC 383 MADISON AVENUE NEW YORK NY US,REMARK=ICD DIVIDEND /OCMT/USD88816,09/ DEBIT REF 2608030367600001,REC GFP=08031522
A88: 1100 | B88: 1100JPMUS783 | C88: +INT_INC | D88: 08/03/2026 | E88: +USD | F88: 228.26 | G88: REMARK=NEXT DAY INTEREST PAYMENT FROM ACCOUNT 000000773093999
...

Sheet 4Q
